Workbook

Sheet Summary
A1: ADT Inc. (NYSE: ADT) - Illustrative Take-Private LBO
A2: Illustrative analysis built from ADT's 10-K, 10-Q and 8-K filings and market data as of Sep 8, 2026.
A4: Transaction overview | D4: Returns (active scenario)
A5: Offer price per share ($) | B5: =Assumptions!$B$30 -> 9.747 | D5: Scenario | F5: =CHOOSE(Assumptions!$B$56,"Base","Downside","Upside","Management case") -> Base
A6: Premium to current price | B6: =Assumptions!$B$29 -> 0.35 | D6: Exit year | F6: ='Returns Analysis'!B4 -> 5
A7: Equity purchase price ($mm) | B7: =Assumptions!$B$31 -> 7395.3438 | D7: Exit EV / EBITDA | F7: ='Returns Analysis'!B6 -> 4.7698212
A8: Entry enterprise value ($mm) | B8: =Assumptions!$B$32 -> 14809.344 | D8: Exit enterprise value ($mm) | F8: ='Returns Analysis'!B7 -> 14166.261
A9: Entry EV / LTM Adj. EBITDA | B9: =Assumptions!$B$33 -> 5.5053323 | D9: Sponsor MOIC (net) | F9: ='Returns Analysis'!B15 -> 1.2593527
A10: Current trading EV / LTM Adj. EBITDA | B10: =Assumptions!$B$26 -> 4.7698212 | D10: Sponsor IRR (net) | F10: ='Returns Analysis'!B16 -> 0.047199619
A11: Total debt / LTM Adj. EBITDA | B11: ='Sources & Uses'!B22 -> 4 | D11: Model checks | F11: =IF(COUNTIF('Returns Analysis'!B30:B34,"OK")=5,"All pass","REVIEW") -> All pass
A12: Sponsor equity ($mm) | B12: ='Sources & Uses'!B15 -> 4576.6272
A13: Equity % of total sources | B13: ='Sources & Uses'!B24 -> 0.29841158
A14: LTM revenue ($mm) | B14: =Assumptions!$B$8 -> 5165
A15: LTM Adjusted EBITDA ($mm) | B15: =Assumptions!$B$12 -> 2690
A17: Scenario comparison
A18: Scenario | B18: Revenue growth | C18: Margin chg / yr | D18: Capex % rev | E18: Exit EV/EBITDA | F18: Net IRR | G18: Net MOIC
A19: Base | B19: =Assumptions!C58 -> 0.02 | C19: =Assumptions!C59 -> 0 | D19: =Assumptions!C60 -> 0.22 | E19: =Sensitivities!H47 -> 4.7698212 | F19: =Sensitivities!C47 -> 0.047199619 | G19: =Sensitivities!D47 -> 1.2593527
A20: Downside | B20: =Assumptions!D58 -> 0 | C20: =Assumptions!D59 -> -0.002 | D20: =Assumptions!D60 -> 0.235 | E20: =Sensitivities!H48 -> 4.2698212 | F20: =Sensitivities!C48 -> -0.13531203 | G20: =Sensitivities!D48 -> 0.48338937
A21: Upside | B21: =Assumptions!E58 -> 0.05 | C21: =Assumptions!E59 -> 0.004 | D21: =Assumptions!E60 -> 0.21 | E21: =Sensitivities!H49 -> 5.7698212 | F21: =Sensitivities!C49 -> 0.22464197 | G21: =Sensitivities!D49 -> 2.7545186
A22: Management case | B22: =Assumptions!F58 -> 0.03 | C22: =Assumptions!F59 -> 0.002 | D22: =Assumptions!F60 -> 0.22 | E22: =Sensitivities!H50 -> 5.5053323 | F22: =Sensitivities!C50 -> 0.14744139 | G22: =Sensitivities!D50 -> 1.9890814
A23: Drivers link to the Assumptions tab; exit multiples and returns come from the scenario data table on the Sensitivities tab, at the hold period set in Assumptions.
A25: Key takeaways
A26: 1. Entry: a 35% premium ($9.75/share) is 5.5x LTM Adj. EBITDA against 4.8x where ADT trades. At 4.0x leverage the sponsor writes a $4.6bn equity check (30% of sources).
A27: 2. Base case (2026 guidance: ~2% growth, flat margin, exit at the unaffected multiple): 4.7% net IRR / 1.26x. A 35% take-private does not earn a typical LBO return on guidance-level fundamentals.
A28: 3. The exit multiple is the largest swing factor: if the premium were retained at exit the same operating case returns 11.2%, and the management case (3% growth, +20bp/yr, entry-multiple exit) returns 14.7%.
A29: 4. Cash flow is thin against the debt load: EBITDA less capex and net subscriber costs covers net interest only 1.7x at the weakest point, and debt falls $1.9bn over five years (net debt/EBITDA 2.8x at exit).
A30: 5. Downside (0% growth, margin erosion, higher capex, lower exit multiple) returns -13.5% / 0.48x, a loss of more than half the equity: a stress case, not a forecast.

Sheet Assumptions
A1: ADT Inc. (NYSE: ADT) - Illustrative Take-Private LBO Model
A2: All figures in $mm unless noted. Blue = input. Black = formula. Green = link to another tab. Yellow = scenario switch.
A4: A. LTM build (LTM Jun-2026 = FY2025 + H1 2026 - H1 2025)
A5: FY2025 Revenue | B5: 5129 | G5: Source: FY2025 10-K / Q4 2025 earnings release: total revenue $5,129mm.
A6: H1 2026 Revenue | B6: 2591 | G6: Source: Q2 2026 10-Q / earnings release (Jul 30, 2026): six months ended Jun 30, 2026.
A7: H1 2025 Revenue | B7: 2555 | G7: Source: same filing, prior-year six months.
A8: LTM Revenue | B8: =$B$5+$B$6-$B$7 -> 5165
A9: FY2025 Adjusted EBITDA | B9: 2680 | G9: Source: FY2025 10-K MD&A: Adjusted EBITDA $2,680mm.
A10: H1 2026 Adjusted EBITDA | B10: 1345 | G10: Q1 2026 $674mm + Q2 2026 $671mm (10-Q: $1,344.3mm; rounded to $mm).
A11: H1 2025 Adjusted EBITDA | B11: 1335 | G11: Q1 2025 $661mm + Q2 2025 $674mm (10-Q: $1,334.4mm; rounded to $mm).
A12: LTM Adjusted EBITDA | B12: =$B$9+$B$10-$B$11 -> 2690
A13: LTM Adjusted EBITDA Margin | B13: =$B$12/$B$8 -> 0.52081317
A15: B. Market data and existing capital structure
A16: Current Share Price ($) | B16: 7.22 | G16: Source: NYSE close Sep 8, 2026 per S&P Capital IQ NetAdvantage ($7.22).
A17: Basic Shares Outstanding (mm) | B17: 730.6 | G17: Source: 10-Q cover (Jul 23, 2026): 675.8mm common + 54.7mm Class B = 730.6mm. Later buybacks are not captured.
A18: Dilutive Securities at Current Price (mm) | B18: =Dilution!F16 -> 19.651945 | G18: Treasury method at the current share price: see Dilution tab.
A19: Dilutive Securities at Offer Price (mm) | B19: =Dilution!E16 -> 28.130255 | G19: Treasury method at the offer price; unvested awards assumed to accelerate. ESTIMATE: see Dilution tab.
A20: Fully Diluted Shares at Offer (mm) | B20: =$B$17+$B$19 -> 758.73026
A21: Current Equity Market Cap (diluted at current price) | B21: =$B$16*($B$17+$B$18) -> 5416.819
A22: Existing Gross Debt | B22: 7418 | G22: Source: 10-Q Note 6 (Jun 30, 2026): term loans $3,609mm + notes $3,750mm + finance leases $58mm. Excludes $416mm receivables facility and the $100mm Term A added Aug 28.
A23: Existing Cash | B23: 4 | G23: Source: Jun 30, 2026 balance sheet: $4mm.
A24: Existing Net Debt | B24: =$B$22-$B$23 -> 7414
A25: Current Enterprise Value | B25: =$B$21+$B$24 -> 12830.819
A26: Current EV / LTM Adj. EBITDA | B26: =$B$25/$B$12 -> 4.7698212
A28: C. Transaction assumptions
A29: Takeover Premium to Current Price | B29: 0.35 | G29: 35%: in line with typical take-private premiums of 25-40%. Sensitized on the Sensitivities tab.
A30: Offer Price / Share ($) | B30: =$B$16*(1+IF(ISNUMBER(Sensitivities!$B$9),Sensitivities!$B$9,$B$29)) -> 9.747
A31: Equity Purchase Price | B31: =$B$30*$B$20 -> 7395.3438
A32: Entry Enterprise Value | B32: =$B$31+$B$24 -> 14809.344
A33: Entry EV / LTM Adj. EBITDA | B33: =$B$32/$B$12 -> 5.5053323
A34: Advisory / Legal / Other Fees (% of Entry EV) | B34: 0.01 | G34: Illustrative.
A35: Financing Fees + OID (% of New Debt) | B35: 0.0225 | G35: Illustrative. Capitalized and amortized (tax-deductible, non-cash).
A36: Financing Fee Amortization Period (years) | B36: 7 | G36: Illustrative; approximates the weighted debt tenor.
A37: Debt Breakage / Call Premiums (% of Existing Gross Debt) | B37: 0.005 | G37: ~$37mm: 1% on ~$3.75bn of notes (101% change-of-control put per 10-K); term loans prepay at par. Illustrative.
A38: Minimum Cash (funded at close, held throughout) | B38: 100 | G38: Illustrative. Revolver is assumed undrawn and is not modeled; see cash check on the Debt Schedule.
A40: D. Financing assumptions
A41: Term Loan B (x LTM Adj. EBITDA) | B41: 3
A42: Senior Notes (x LTM Adj. EBITDA) | B42: 1
A43: Total Leverage (x LTM Adj. EBITDA) | B43: =$B$41+$B$42 -> 4
A44: SOFR | B44: 0.036 | G44: Fed funds target range 3.50%-3.75% as of mid-2026, so SOFR is ~3.6%. Update for current curve.
...

Sheet Dilution
A1: Dilution: treasury method at the offer price and at the current price (mm shares)
A2: Counts are from the 10-K equity note (Dec 31, 2025) plus 2026 grants disclosed in the 10-Q. ESTIMATE: the 10-Q has no full award roll-forward.
A4: Offer price ($) | B4: =Assumptions!$B$30 -> 9.747
A5: Current share price ($) | B5: =Assumptions!$B$16 -> 7.22
A7: Award | B7: Number (mm) | C7: Strike ($) | D7: % vesting | E7: Net shares: offer | F7: Net shares: current
A8: 2018 Plan options outstanding at Dec 31 2025 (10-K, WAEP $6.97) | B8: 25.172 | C8: 6.97 | D8: 1 | E8: =IF($B$4>C8,B8*D8*(1-C8/$B$4),0) -> 7.1717086 | F8: =IF($B$5>C8,B8*D8*(1-C8/$B$5),0) -> 0.87160665
A9: 2026 executive option grant (10-Q: ~9mm at $6.74) | B9: 9 | C9: 6.74 | D9: 1 | E9: =IF($B$4>C9,B9*D9*(1-C9/$B$4),0) -> 2.7765466 | F9: =IF($B$5>C9,B9*D9*(1-C9/$B$5),0) -> 0.59833795
A10: Top-up options, service tranche (10-K, $13.30) | B10: 5.955 | C10: 13.3 | D10: 1 | E10: =IF($B$4>C10,B10*D10*(1-C10/$B$4),0) -> 0 | F10: =IF($B$5>C10,B10*D10*(1-C10/$B$5),0) -> 0
A11: Top-up options, performance tranche (10-K, $13.30) | B11: 5.625 | C11: 13.3 | D11: 1 | E11: =IF($B$4>C11,B11*D11*(1-C11/$B$4),0) -> 0 | F11: =IF($B$5>C11,B11*D11*(1-C11/$B$5),0) -> 0
A12: Unvested RSUs incl. DEUs at Dec 31 2025 (10-K) | B12: 7.982 | C12: 0 | D12: 1 | E12: =IF($B$4>C12,B12*D12*(1-C12/$B$4),0) -> 7.982 | F12: =IF($B$5>C12,B12*D12*(1-C12/$B$5),0) -> 7.982
A13: 2026 annual RSU grant (10-Q: ~4mm) | B13: 4 | C13: 0 | D13: 1 | E13: =IF($B$4>C13,B13*D13*(1-C13/$B$4),0) -> 4 | F13: =IF($B$5>C13,B13*D13*(1-C13/$B$5),0) -> 4
A14: Origin AI retention awards (10-Q: ~8mm; 5mm performance-based) | B14: 8 | C14: 0 | D14: 1 | E14: =IF($B$4>C14,B14*D14*(1-C14/$B$4),0) -> 8 | F14: =IF($B$5>C14,B14*D14*(1-C14/$B$5),0) -> 8
A15: Less: est. H1-26 RSU vesting already in basic count (ESTIMATE) | B15: -1.8 | C15: 0 | D15: 1 | E15: =IF($B$4>C15,B15*D15*(1-C15/$B$4),0) -> -1.8 | F15: =IF($B$5>C15,B15*D15*(1-C15/$B$5),0) -> -1.8
A16: Total dilutive securities (mm) | E16: =SUM(E8:E15) -> 28.130255 | F16: =SUM(F8:F15) -> 19.651945
A18: Method: net new shares = number x % vesting x (1 - strike / price) if the award is in the money; RSUs have no strike, so all count.
A19: Assumes all unvested RSUs and service options accelerate on a change of control and that Origin AI performance awards vest in full (conservative for a buyer). Change the vesting % to test.
A20: Cross-check: ADT's Q2 2026 diluted EPS share count implies only ~4mm of dilution, but that uses unrecognized compensation as assumed proceeds and market prices; a buyout accelerates unvested awards.
A21: H1 2026 RSU vesting is already inside the 730.6mm basic count; the last row is an ESTIMATE (about half of FY2025's 3.6mm vested) to avoid double counting. Replace with the Q3 10-Q roll-forward when available.

Sheet Sources & Uses
A1: Sources & Uses ($mm)
A3: Uses of Funds | B3: $mm | C3: % of Total | D3: x LTM EBITDA
A4: Equity Purchase Price | B4: =Assumptions!$B$31 -> 7395.3438 | C4: =B4/$B$10 -> 0.48220144 | D4: =B4/Assumptions!$B$12 -> 2.7491984
A5: Refinance Existing Net Debt | B5: =Assumptions!$B$24 -> 7414 | C5: =B5/$B$10 -> 0.48341789 | D5: =B5/Assumptions!$B$12 -> 2.7561338
A6: Advisory & Other Transaction Fees | B6: =Assumptions!$B$34*Assumptions!$B$32 -> 148.09344 | C6: =B6/$B$10 -> 0.0096561934 | D6: =B6/Assumptions!$B$12 -> 0.055053323
A7: Financing Fees & OID | B7: =Assumptions!$B$35*(B13+B14) -> 242.1 | C7: =B7/$B$10 -> 0.015785739 | D7: =B7/Assumptions!$B$12 -> 0.09
A8: Debt Breakage / Call Premiums | B8: =Assumptions!$B$37*Assumptions!$B$22 -> 37.09 | C8: =B8/$B$10 -> 0.0024183935 | D8: =B8/Assumptions!$B$12 -> 0.013788104
A9: Minimum Cash to Balance Sheet | B9: =Assumptions!$B$38 -> 100 | C9: =B9/$B$10 -> 0.0065203384 | D9: =B9/Assumptions!$B$12 -> 0.037174721
A10: Total Uses | B10: =SUM(B4:B9) -> 15336.627 | C10: =SUM(C4:C9) -> 1 | D10: =B10/Assumptions!$B$12 -> 5.7013484
A12: Sources of Funds | B12: $mm | C12: % of Total | D12: x LTM EBITDA
A13: Term Loan B | B13: =IF(ISNUMBER(Sensitivities!$B$8),Sensitivities!$B$8-Assumptions!$B$42,Assumptions!$B$41)*Assumptions!$B$12 -> 8070 | C13: =B13/$B$16 -> 0.52619131 | D13: =B13/Assumptions!$B$12 -> 3
A14: Senior Notes | B14: =Assumptions!$B$42*Assumptions!$B$12 -> 2690 | C14: =B14/$B$16 -> 0.1753971 | D14: =B14/Assumptions!$B$12 -> 1
A15: Sponsor Equity (plug) | B15: =B10-B13-B14 -> 4576.6272 | C15: =B15/$B$16 -> 0.29841158 | D15: =B15/Assumptions!$B$12 -> 1.7013484
A16: Total Sources | B16: =SUM(B13:B15) -> 15336.627 | C16: =SUM(C13:C15) -> 1 | D16: =B16/Assumptions!$B$12 -> 5.7013484
A17: Check: Sources - Uses | B17: =B16-B10 -> 0
A19: Entry metrics
A20: Entry EV / LTM Adj. EBITDA | B20: =Assumptions!$B$33 -> 5.5053323
A21: Entry EV / (LTM EBITDA - capex - net SAC) | B21: =Assumptions!$B$32/(Assumptions!$B$12-(Assumptions!$B$60+Assumptions!$B$64)*Assumptions!$B$8) -> 10.78671
A22: Total Debt / LTM Adj. EBITDA | B22: =(B13+B14)/Assumptions!$B$12 -> 4
A23: Net Debt at Close / LTM Adj. EBITDA | B23: =(B13+B14-B9)/Assumptions!$B$12 -> 3.9628253
A24: Equity % of Total Sources | B24: =B15/B16 -> 0.29841158
A25: Offer Price / Share ($) | B25: =Assumptions!$B$30 -> 9.747
A27: EBITDA is ADT's Adjusted EBITDA, which excludes capitalized subscriber costs; the second multiple (row 21) shows entry value on a cash-earnings basis.

Sheet Operating Model
A1: Operating Model ($mm)
B3: 0 | C3: 1 | D3: 2 | E3: 3 | F3: 4 | G3: 5
A4: Revenue | B4: =Assumptions!$B$8 -> 5165 | C4: =B4*(1+Assumptions!$B$58) -> 5268.3 | D4: =C4*(1+Assumptions!$B$58) -> 5373.666 | E4: =D4*(1+Assumptions!$B$58) -> 5481.1393 | F4: =E4*(1+Assumptions!$B$58) -> 5590.7621 | G4: =F4*(1+Assumptions!$B$58) -> 5702.5773
A5: Revenue Growth % | C5: =C4/B4-1 -> 0.02 | D5: =D4/C4-1 -> 0.02 | E5: =E4/D4-1 -> 0.02 | F5: =F4/E4-1 -> 0.02 | G5: =G4/F4-1 -> 0.02
A6: EBITDA Margin % | B6: =B7/B4 -> 0.52081317 | C6: =$B$6+Assumptions!$B$59*C$3 -> 0.52081317 | D6: =$B$6+Assumptions!$B$59*D$3 -> 0.52081317 | E6: =$B$6+Assumptions!$B$59*E$3 -> 0.52081317 | F6: =$B$6+Assumptions!$B$59*F$3 -> 0.52081317 | G6: =$B$6+Assumptions!$B$59*G$3 -> 0.52081317
A7: EBITDA | B7: =Assumptions!$B$12 -> 2690 | C7: =C4*C6 -> 2743.8 | D7: =D4*D6 -> 2798.676 | E7: =E4*E6 -> 2854.6495 | F7: =F4*F6 -> 2911.7425 | G7: =G4*G6 -> 2969.9774
A8: Less: D&A | C8: =C22*Assumptions!$B$65 -> 1159.026 | D8: =D22*Assumptions!$B$65 -> 1182.2065 | E8: =E22*Assumptions!$B$65 -> 1205.8507 | F8: =F22*Assumptions!$B$65 -> 1229.9677 | G8: =G22*Assumptions!$B$65 -> 1254.567
A9: EBIT | C9: =C7-C8 -> 1584.774 | D9: =D7-D8 -> 1616.4695 | E9: =E7-E8 -> 1648.7989 | F9: =F7-F8 -> 1681.7748 | G9: =G7-G8 -> 1715.4103
A10: Less: Interest Expense - Term Loan B | C10: ='Debt Schedule'!C7 -> 572.97 | D10: ='Debt Schedule'!D7 -> 550.67249 | E10: ='Debt Schedule'!E7 -> 526.35237 | F10: ='Debt Schedule'!F7 -> 499.89765 | G10: ='Debt Schedule'!G7 -> 471.19093
A11: Less: Interest Expense - Senior Notes | C11: ='Debt Schedule'!C16 -> 228.65 | D11: ='Debt Schedule'!D16 -> 228.65 | E11: ='Debt Schedule'!E16 -> 228.65 | F11: ='Debt Schedule'!F16 -> 228.65 | G11: ='Debt Schedule'!G16 -> 228.65
A12: Plus: Interest Income on Cash | C12: ='Debt Schedule'!C26 -> 3 | D12: ='Debt Schedule'!D26 -> 5.3334939 | E12: ='Debt Schedule'!E26 -> 7.9518638 | F12: ='Debt Schedule'!F26 -> 10.87088 | G12: ='Debt Schedule'!G26 -> 14.10708
A13: Net Interest Expense (incl. receivables facility) | C13: =C10+C11+'Debt Schedule'!C39-C12 -> 817.548 | D13: =D10+D11+'Debt Schedule'!D39-D12 -> 792.917 | E13: =E10+E11+'Debt Schedule'!E39-E12 -> 765.9785 | F13: =F10+F11+'Debt Schedule'!F39-F12 -> 736.60477 | G13: =G10+G11+'Debt Schedule'!G39-G12 -> 704.66185
A14: Less: Amortization of Financing Fees | C14: =IF(C$3<=Assumptions!$B$36,'Sources & Uses'!$B$7/Assumptions!$B$36,0) -> 34.585714 | D14: =IF(D$3<=Assumptions!$B$36,'Sources & Uses'!$B$7/Assumptions!$B$36,0) -> 34.585714 | E14: =IF(E$3<=Assumptions!$B$36,'Sources & Uses'!$B$7/Assumptions!$B$36,0) -> 34.585714 | F14: =IF(F$3<=Assumptions!$B$36,'Sources & Uses'!$B$7/Assumptions!$B$36,0) -> 34.585714 | G14: =IF(G$3<=Assumptions!$B$36,'Sources & Uses'!$B$7/Assumptions!$B$36,0) -> 34.585714
A15: EBT (Pre-Tax Income) | C15: =C9-C13-C14 -> 732.64029 | D15: =D9-D13-D14 -> 788.96677 | E15: =E9-E13-E14 -> 848.23465 | F15: =F9-F13-F14 -> 910.58436 | G15: =G9-G13-G14 -> 976.16278
A16: Plus: Interest Disallowed under Sec. 163(j) | C16: =MAX(C13-Assumptions!$B$68*C7,0) -> 0 | D16: =MAX(D13-Assumptions!$B$68*D7,0) -> 0 | E16: =MAX(E13-Assumptions!$B$68*E7,0) -> 0 | F16: =MAX(F13-Assumptions!$B$68*F7,0) -> 0 | G16: =MAX(G13-Assumptions!$B$68*G7,0) -> 0
A17: Taxable Income | C17: =C15+C16 -> 732.64029 | D17: =D15+D16 -> 788.96677 | E17: =E15+E16 -> 848.23465 | F17: =F15+F16 -> 910.58436 | G17: =G15+G16 -> 976.16278
A18: Less: Taxes | C18: =MAX(C17,0)*Assumptions!$B$67 -> 190.48647 | D18: =MAX(D17,0)*Assumptions!$B$67 -> 205.13136 | E18: =MAX(E17,0)*Assumptions!$B$67 -> 220.54101 | F18: =MAX(F17,0)*Assumptions!$B$67 -> 236.75193 | G18: =MAX(G17,0)*Assumptions!$B$67 -> 253.80232
A19: Net Income | C19: =C15-C18 -> 542.15381 | D19: =D15-D18 -> 583.83541 | E19: =E15-E18 -> 627.69364 | F19: =F15-F18 -> 673.83242 | G19: =G15-G18 -> 722.36045
A20: (+) D&A | C20: =C8 -> 1159.026 | D20: =D8 -> 1182.2065 | E20: =E8 -> 1205.8507 | F20: =F8 -> 1229.9677 | G20: =G8 -> 1254.567
A21: (+) Financing Fee Amortization (non-cash) | C21: =C14 -> 34.585714 | D21: =D14 -> 34.585714 | E21: =E14 -> 34.585714 | F21: =F14 -> 34.585714 | G21: =G14 -> 34.585714
A22: (-) Capex (all-in) | C22: =C4*Assumptions!$B$60 -> 1159.026 | D22: =D4*Assumptions!$B$60 -> 1182.2065 | E22: =E4*Assumptions!$B$60 -> 1205.8507 | F22: =F4*Assumptions!$B$60 -> 1229.9677 | G22: =G4*Assumptions!$B$60 -> 1254.567
A23: (-) Net Subscriber Acquisition Costs | C23: =C4*Assumptions!$B$64 -> 184.3905 | D23: =D4*Assumptions!$B$64 -> 188.07831 | E23: =E4*Assumptions!$B$64 -> 191.83988 | F23: =F4*Assumptions!$B$64 -> 195.67667 | G23: =G4*Assumptions!$B$64 -> 199.59021
A24: (-) Increase in NWC | C24: =(C4-B4)*Assumptions!$B$66 -> 0.5165 | D24: =(D4-C4)*Assumptions!$B$66 -> 0.52683 | E24: =(E4-D4)*Assumptions!$B$66 -> 0.5373666 | F24: =(F4-E4)*Assumptions!$B$66 -> 0.54811393 | G24: =(G4-F4)*Assumptions!$B$66 -> 0.55907621
A25: Free Cash Flow (Pre-Debt Paydown) | C25: =C19+C20+C21-C22-C23-C24 -> 391.83253 | D25: =D19+D20+D21-D22-D23-D24 -> 429.81598 | E25: =E19+E20+E21-E22-E23-E24 -> 469.90211 | F25: =F19+F20+F21-F22-F23-F24 -> 512.19335 | G25: =G19+G20+G21-G22-G23-G24 -> 556.79689
A27: Memo: Capex % of Revenue | C27: =C22/C4 -> 0.22 | D27: =D22/D4 -> 0.22 | E27: =E22/E4 -> 0.22 | F27: =F22/F4 -> 0.22 | G27: =G22/G4 -> 0.22
A28: Memo: EBITDA - Capex - Net SAC | B28: =B7-Assumptions!$B$60*B4-Assumptions!$B$64*B4 -> 1372.925 | C28: =C7-C22-C23 -> 1400.3835 | D28: =D7-D22-D23 -> 1428.3912 | E28: =E7-E22-E23 -> 1456.959 | F28: =F7-F22-F23 -> 1486.0982 | G28: =G7-G22-G23 -> 1515.8201
A29: Memo: Cash Conversion (% of EBITDA) | B29: =B28/B7 -> 0.51038104 | C29: =C28/C7 -> 0.51038104 | D29: =D28/D7 -> 0.51038104 | E29: =E28/E7 -> 0.51038104 | F29: =F28/F7 -> 0.51038104 | G29: =G28/G7 -> 0.51038104
A30: Memo: Receivables Facility Interest (included in Net Interest) | C30: ='Debt Schedule'!C39 -> 18.928 | D30: ='Debt Schedule'!D39 -> 18.928 | E30: ='Debt Schedule'!E39 -> 18.928 | F30: ='Debt Schedule'!F39 -> 18.928 | G30: ='Debt Schedule'!G39 -> 18.928

Sheet Debt Schedule
A1: Debt Schedule ($mm)
A2: Interest is calculated on BEGINNING-of-period balances (no circular reference). Cash not swept accumulates and is credited at exit.
B3: 0 | C3: 1 | D3: 2 | E3: 3 | F3: 4 | G3: 5
A4: Term Loan B
A5: Beginning Balance | C5: =B11 -> 8070 | D5: =C11 -> 7755.9506 | E5: =D11 -> 7413.4136 | F5: =E11 -> 7040.812 | G5: =F11 -> 6636.492
A6: Interest Rate (SOFR + spread) | C6: =Assumptions!$B$44+Assumptions!$B$45*(C$3-1)+Assumptions!$B$46 -> 0.071 | D6: =Assumptions!$B$44+Assumptions!$B$45*(D$3-1)+Assumptions!$B$46 -> 0.071 | E6: =Assumptions!$B$44+Assumptions!$B$45*(E$3-1)+Assumptions!$B$46 -> 0.071 | F6: =Assumptions!$B$44+Assumptions!$B$45*(F$3-1)+Assumptions!$B$46 -> 0.071 | G6: =Assumptions!$B$44+Assumptions!$B$45*(G$3-1)+Assumptions!$B$46 -> 0.071
A7: Interest Expense | C7: =C5*C6 -> 572.97 | D7: =D5*D6 -> 550.67249 | E7: =E5*E6 -> 526.35237 | F7: =F5*F6 -> 499.89765 | G7: =G5*G6 -> 471.19093
A8: Mandatory Amortization | C8: =MIN(Assumptions!$B$48*$B$11,C5) -> 80.7 | D8: =MIN(Assumptions!$B$48*$B$11,D5) -> 80.7 | E8: =MIN(Assumptions!$B$48*$B$11,E5) -> 80.7 | F8: =MIN(Assumptions!$B$48*$B$11,F5) -> 80.7 | G8: =MIN(Assumptions!$B$48*$B$11,G5) -> 80.7
A9: FCF Available for Sweep | C9: =MAX('Operating Model'!C25-C8,0) -> 311.13253 | D9: =MAX('Operating Model'!D25-D8,0) -> 349.11598 | E9: =MAX('Operating Model'!E25-E8,0) -> 389.20211 | F9: =MAX('Operating Model'!F25-F8,0) -> 431.49335 | G9: =MAX('Operating Model'!G25-G8,0) -> 476.09689
A10: Cash Sweep | C10: =MIN(C9*Assumptions!$B$49,C5-C8) -> 233.34939 | D10: =MIN(D9*Assumptions!$B$49,D5-D8) -> 261.83699 | E10: =MIN(E9*Assumptions!$B$49,E5-E8) -> 291.90159 | F10: =MIN(F9*Assumptions!$B$49,F5-F8) -> 323.62001 | G10: =MIN(G9*Assumptions!$B$49,G5-G8) -> 357.07266
A11: Ending Balance | B11: ='Sources & Uses'!B13 -> 8070 | C11: =C5-C8-C10 -> 7755.9506 | D11: =D5-D8-D10 -> 7413.4136 | E11: =E5-E8-E10 -> 7040.812 | F11: =F5-F8-F10 -> 6636.492 | G11: =G5-G8-G10 -> 6198.7194
A13: Senior Notes (bullet, no amortization)
A14: Beginning Balance | C14: =B17 -> 2690 | D14: =C17 -> 2690 | E14: =D17 -> 2690 | F14: =E17 -> 2690 | G14: =F17 -> 2690
A15: Interest Rate | C15: =Assumptions!$B$47 -> 0.085 | D15: =Assumptions!$B$47 -> 0.085 | E15: =Assumptions!$B$47 -> 0.085 | F15: =Assumptions!$B$47 -> 0.085 | G15: =Assumptions!$B$47 -> 0.085
A16: Interest Expense | C16: =C14*C15 -> 228.65 | D16: =D14*D15 -> 228.65 | E16: =E14*E15 -> 228.65 | F16: =F14*F15 -> 228.65 | G16: =G14*G15 -> 228.65
A17: Ending Balance | B17: ='Sources & Uses'!B14 -> 2690 | C17: =C14 -> 2690 | D17: =D14 -> 2690 | E17: =E14 -> 2690 | F17: =F14 -> 2690 | G17: =G14 -> 2690
A19: Cash
A20: Beginning Balance | C20: =B24 -> 100 | D20: =C24 -> 177.78313 | E20: =D24 -> 265.06213 | F20: =E24 -> 362.36266 | G20: =F24 -> 470.23599
A21: Plus: Free Cash Flow (Pre-Debt Paydown) | C21: ='Operating Model'!C25 -> 391.83253 | D21: ='Operating Model'!D25 -> 429.81598 | E21: ='Operating Model'!E25 -> 469.90211 | F21: ='Operating Model'!F25 -> 512.19335 | G21: ='Operating Model'!G25 -> 556.79689
A22: Less: Mandatory Amortization | C22: =C8 -> 80.7 | D22: =D8 -> 80.7 | E22: =E8 -> 80.7 | F22: =F8 -> 80.7 | G22: =G8 -> 80.7
A23: Less: Cash Sweep | C23: =C10 -> 233.34939 | D23: =D10 -> 261.83699 | E23: =E10 -> 291.90159 | F23: =F10 -> 323.62001 | G23: =G10 -> 357.07266
A24: Ending Balance | B24: =Assumptions!$B$38 -> 100 | C24: =C20+C21-C22-C23 -> 177.78313 | D24: =D20+D21-D22-D23 -> 265.06213 | E24: =E20+E21-E22-E23 -> 362.36266 | F24: =F20+F21-F22-F23 -> 470.23599 | G24: =G20+G21-G22-G23 -> 589.26021
A25: Interest Rate on Cash | C25: =Assumptions!$B$50 -> 0.03 | D25: =Assumptions!$B$50 -> 0.03 | E25: =Assumptions!$B$50 -> 0.03 | F25: =Assumptions!$B$50 -> 0.03 | G25: =Assumptions!$B$50 -> 0.03
A26: Interest Income | C26: =C20*C25 -> 3 | D26: =D20*D25 -> 5.3334939 | E26: =E20*E25 -> 7.9518638 | F26: =F20*F25 -> 10.87088 | G26: =G20*G25 -> 14.10708
A27: Check: Ending Cash >= Minimum Cash | C27: =IF(C24>=Assumptions!$B$38-0.001,"OK","SHORTFALL") -> OK | D27: =IF(D24>=Assumptions!$B$38-0.001,"OK","SHORTFALL") -> OK | E27: =IF(E24>=Assumptions!$B$38-0.001,"OK","SHORTFALL") -> OK | F27: =IF(F24>=Assumptions!$B$38-0.001,"OK","SHORTFALL") -> OK | G27: =IF(G24>=Assumptions!$B$38-0.001,"OK","SHORTFALL") -> OK
A29: Total Debt (Ending) | B29: =B11+B17 -> 10760 | C29: =C11+C17 -> 10445.951 | D29: =D11+D17 -> 10103.414 | E29: =E11+E17 -> 9730.812 | F29: =F11+F17 -> 9326.492 | G29: =G11+G17 -> 8888.7194
A30: Net Debt (Ending) | B30: =B29-B24 -> 10660 | C30: =C29-C24 -> 10268.167 | D30: =D29-D24 -> 9838.3515 | E30: =E29-E24 -> 9368.4494 | F30: =F29-F24 -> 8856.256 | G30: =G29-G24 -> 8299.4591
A31: Total Debt / EBITDA | B31: =B29/'Operating Model'!B7 -> 4 | C31: =C29/'Operating Model'!C7 -> 3.8071108 | D31: =D29/'Operating Model'!D7 -> 3.6100691 | E31: =E29/'Operating Model'!E7 -> 3.4087589 | F31: =F29/'Operating Model'!F7 -> 3.2030621 | G31: =G29/'Operating Model'!G7 -> 2.9928576
A32: Net Debt / EBITDA | B32: =B30/'Operating Model'!B7 -> 3.9628253 | C32: =C30/'Operating Model'!C7 -> 3.7423163 | D32: =D30/'Operating Model'!D7 -> 3.5153592 | E32: =E30/'Operating Model'!E7 -> 3.2818212 | F32: =F30/'Operating Model'!F7 -> 3.0415657 | G32: =G30/'Operating Model'!G7 -> 2.794452
A33: EBITDA / Net Interest | C33: ='Operating Model'!C7/'Operating Model'!C13 -> 3.3561332 | D33: ='Operating Model'!D7/'Operating Model'!D13 -> 3.5295952 | E33: ='Operating Model'!E7/'Operating Model'!E13 -> 3.7268011 | F33: ='Operating Model'!F7/'Operating Model'!F13 -> 3.9529238 | G33: ='Operating Model'!G7/'Operating Model'!G13 -> 4.2147554
A34: (EBITDA - Capex - Net SAC) / Net Interest | C34: ='Operating Model'!C28/'Operating Model'!C13 -> 1.7129068 | D34: ='Operating Model'!D28/'Operating Model'!D13 -> 1.8014385 | E34: ='Operating Model'!E28/'Operating Model'!E13 -> 1.9020886 | F34: ='Operating Model'!F28/'Operating Model'!F13 -> 2.0174973 | G34: ='Operating Model'!G28/'Operating Model'!G13 -> 2.1511313
A36: Receivables Facility (stays in place; excluded from net debt per ADT)
A37: Balance | B37: =Assumptions!$B$51 -> 416 | C37: =Assumptions!$B$51 -> 416 | D37: =Assumptions!$B$51 -> 416 | E37: =Assumptions!$B$51 -> 416 | F37: =Assumptions!$B$51 -> 416 | G37: =Assumptions!$B$51 -> 416
A38: Receivables Facility Interest Rate (SOFR + spread) | C38: =Assumptions!$B$44+Assumptions!$B$45*(C$3-1)+Assumptions!$B$52 -> 0.0455 | D38: =Assumptions!$B$44+Assumptions!$B$45*(D$3-1)+Assumptions!$B$52 -> 0.0455 | E38: =Assumptions!$B$44+Assumptions!$B$45*(E$3-1)+Assumptions!$B$52 -> 0.0455 | F38: =Assumptions!$B$44+Assumptions!$B$45*(F$3-1)+Assumptions!$B$52 -> 0.0455 | G38: =Assumptions!$B$44+Assumptions!$B$45*(G$3-1)+Assumptions!$B$52 -> 0.0455
A39: Receivables Facility Interest Expense | C39: =C37*C38 -> 18.928 | D39: =D37*D38 -> 18.928 | E39: =E37*E38 -> 18.928 | F39: =F37*F38 -> 18.928 | G39: =G37*G38 -> 18.928

Sheet Returns Analysis
A1: Returns Analysis ($mm)
A3: Exit Calculation
A4: Exit Year (hold period) | B4: =Assumptions!$B$72 -> 5
A5: Exit-Year EBITDA | B5: =INDEX('Operating Model'!$C$7:$G$7,B4) -> 2969.9774
A6: Exit EV / EBITDA Multiple | B6: =Assumptions!$B$73 -> 4.7698212
A7: Exit Enterprise Value | B7: =B5*B6 -> 14166.261
A8: Less: Debt at Exit | B8: =INDEX('Debt Schedule'!$C$29:$G$29,B4) -> 8888.7194
A9: Plus: Cash at Exit | B9: =INDEX('Debt Schedule'!$C$24:$G$24,B4) -> 589.26021
A10: Exit Equity Value (100%) | B10: =B7-B8+B9 -> 5866.8018
A11: Less: Management Option Pool | B11: =Assumptions!$B$69*MAX(B10-B14,0) -> 103.21397
A12: Sponsor Exit Proceeds | B12: =B10-B11 -> 5763.5879
A13: Sponsor Returns
A14: Sponsor Equity Invested (Year 0) | B14: ='Sources & Uses'!B15 -> 4576.6272
A15: MOIC (net of option pool) | B15: =B12/B14 -> 1.2593527
A16: IRR (net of option pool) | B16: =IF(B15>0,B15^(1/B4)-1,-1) -> 0.047199619
A17: Gross MOIC (pre option pool) | B17: =B10/B14 -> 1.2819051
A18: Gross IRR (pre option pool) | B18: =IF(B17>0,B17^(1/B4)-1,-1) -> 0.050923675
A20: Value Creation Bridge (sponsor, net of option pool)
A21: EBITDA Growth (at entry multiple) | B21: =(B5-Assumptions!$B$12)*Assumptions!$B$33 -> 1541.3684
A22: Multiple Change (exit vs. entry multiple) | B22: =(B6-Assumptions!$B$33)*B5 -> -2184.4512
A23: Net Debt Reduction (paydown + cash build) | B23: =('Debt Schedule'!B29-Assumptions!$B$38)-INDEX('Debt Schedule'!$C$30:$G$30,B4) -> 2360.5409
A24: Less: Transaction, Financing & Breakage Costs | B24: =-('Sources & Uses'!B6+'Sources & Uses'!B7+'Sources & Uses'!B8) -> -427.28344
A25: Less: Management Option Pool | B25: =-B11 -> -103.21397
A26: Total Sponsor Value Created | B26: =SUM(B21:B25) -> 1186.9606
A27: Check: Bridge vs. Actual (should be 0) | B27: =B26-(B12-B14) -> 0
A29: Model checks
A30: Sources = Uses | B30: =IF(ABS('Sources & Uses'!B17)<0.01,"OK","ERROR") -> OK
A31: Value bridge foots | B31: =IF(ABS(B27)<0.01,"OK","ERROR") -> OK
A32: Minimum cash maintained in every year | B32: =IF(COUNTIF('Debt Schedule'!C27:G27,"OK")=5,"OK","REVIEW: revolver would be drawn") -> OK
A33: Term Loan B balance never negative | B33: =IF(MIN('Debt Schedule'!C11:G11)>=-0.001,"OK","ERROR") -> OK
A34: Sensitivity input cells are blank | B34: =IF(COUNTA(Sensitivities!B5:B10)=0,"OK","ERROR: clear Sensitivities!B5:B10") -> OK
A36: Sensitivity: exit multiple (live; debt paydown is unaffected by exit multiple)
A37: Change vs. base exit multiple (turns) | C37: -1 | D37: -0.5 | E37: 0 | F37: 0.5 | G37: 1
A38: Exit EV / EBITDA | C38: =$B$6+C37 -> 3.7698212 | D38: =$B$6+D37 -> 4.2698212 | E38: =$B$6+E37 -> 4.7698212 | F38: =$B$6+F37 -> 5.2698212 | G38: =$B$6+G37 -> 5.7698212
A39: Sponsor MOIC (net of option pool) | C39: =((C38*$B$5-$B$8+$B$9)-Assumptions!$B$69*MAX((C38*$B$5-$B$8+$B$9)-$B$14,0))/$B$14 -> 0.63296055 | D39: =((D38*$B$5-$B$8+$B$9)-Assumptions!$B$69*MAX((D38*$B$5-$B$8+$B$9)-$B$14,0))/$B$14 -> 0.95743283 | E39: =((E38*$B$5-$B$8+$B$9)-Assumptions!$B$69*MAX((E38*$B$5-$B$8+$B$9)-$B$14,0))/$B$14 -> 1.2593527 | F39: =((F38*$B$5-$B$8+$B$9)-Assumptions!$B$69*MAX((F38*$B$5-$B$8+$B$9)-$B$14,0))/$B$14 -> 1.5578672 | G39: =((G38*$B$5-$B$8+$B$9)-Assumptions!$B$69*MAX((G38*$B$5-$B$8+$B$9)-$B$14,0))/$B$14 -> 1.8563817
A40: Sponsor IRR (net of option pool) | C40: =IF(C39>0,C39^(1/$B$4)-1,-1) -> -0.087410792 | D40: =IF(D39>0,D39^(1/$B$4)-1,-1) -> -0.0086622073 | E40: =IF(E39>0,E39^(1/$B$4)-1,-1) -> 0.047199619 | F40: =IF(F39>0,F39^(1/$B$4)-1,-1) -> 0.092712942 | G40: =IF(G39>0,G39^(1/$B$4)-1,-1) -> 0.13170558
A42: Credit statistics over the hold period
A43: Net Debt / EBITDA at Exit | B43: =INDEX('Debt Schedule'!$C$32:$G$32,B4) -> 2.794452
A44: Minimum EBITDA / Net Interest | B44: =MIN('Debt Schedule'!$C$33:INDEX('Debt Schedule'!$C$33:$G$33,B4)) -> 3.3561332
A45: Minimum (EBITDA - Capex - Net SAC) / Net Interest | B45: =MIN('Debt Schedule'!$C$34:INDEX('Debt Schedule'!$C$34:$G$34,B4)) -> 1.7129068

Sheet Sensitivities
A1: Sensitivities: sponsor IRR / MOIC (net of option pool)
A2: Excel data tables (Data > What-If Analysis > Data Table): each cell re-runs the full model for the active scenario and hold period. Press F9 if calculation is set to 'automatic except tables'.
A4: Data table input cells (leave blank: the tables write to these cells)
A5: Revenue growth | C5: When a cell here is blank, the model uses the Assumptions tab.
A6: Exit multiple change vs. current multiple (turns)
A7: All-in capex % of revenue
A8: Total leverage (x LTM Adj. EBITDA)
A9: Takeover premium
A10: Scenario (1-4)
A12: IRR: revenue growth vs. exit multiple (turns vs. CURRENT trading multiple)
A13: ='Returns Analysis'!B16 -> 0.047199619 | B13: -1 | C13: -0.5 | D13: 0 | E13: 0.5 | F13: 1
A14: 0 | B14: -0.19740213 | C14: -0.08915941 | D14: -0.016366169 | E14: 0.036707149 | F14: 0.07978813
A15: 0.01 | B15: -0.13636169 | C15: -0.046210333 | D15: 0.01745149 | E15: 0.065688673 | F15: 0.10650384
A16: 0.02 | B16: -0.087410792 | C16: -0.0086622073 | D16: 0.047199619 | E16: 0.092712942 | F16: 0.13170558
A17: 0.03 | B17: -0.04583397 | C17: 0.023118521 | D17: 0.074830755 | E17: 0.11816308 | F17: 0.15566342
A18: 0.04 | B18: -0.0092498988 | C18: 0.051787372 | D18: 0.10076697 | E18: 0.14231966 | F18: 0.17858094
A20: MOIC: revenue growth vs. exit multiple
A21: ='Returns Analysis'!B15 -> 1.2593527 | B21: -1 | C21: -0.5 | D21: 0 | E21: 0.5 | F21: 1
A22: 0 | B22: 0.3330351 | C22: 0.62691965 | D22: 0.92080419 | E22: 1.1975136 | F22: 1.4678874
A23: 0.01 | B23: 0.48046249 | C23: 0.7893381 | D23: 1.0903566 | E23: 1.3745222 | F23: 1.6586877
A24: 0.02 | B24: 0.63296055 | C24: 0.95743283 | D24: 1.2593527 | E24: 1.5578672 | F24: 1.8563817
A25: 0.03 | B25: 0.79089668 | C25: 1.1210623 | D25: 1.4344996 | E25: 1.7479369 | F25: 2.0613742
A26: 0.04 | B26: 0.95459823 | C26: 1.2871814 | D26: 1.6161325 | E26: 1.9450835 | F26: 2.2740345
A28: IRR: all-in capex % of revenue vs. total leverage (Senior Notes fixed at 1.0x; rest is TLB)
A29: ='Returns Analysis'!B16 -> 0.047199619 | B29: 3 | C29: 3.5 | D29: 4 | E29: 4.25 | F29: 4.5
A30: 0.19 | B30: 0.062513938 | C30: 0.064868851 | D30: 0.06853507 | E30: 0.070791549 | F30: 0.073245499
A31: 0.205 | B31: 0.055770141 | C31: 0.056670677 | D31: 0.058082419 | E31: 0.058648111 | F31: 0.058585672
A32: 0.22 | B32: 0.048849502 | C32: 0.048209891 | D32: 0.047199619 | E32: 0.045881686 | F32: 0.043065694
A33: 0.235 | B33: 0.041741231 | C33: 0.039466771 | D33: 0.035844672 | E33: 0.032459668 | F33: 0.026562947
A34: 0.25 | B34: 0.03443348 | C34: 0.030419194 | D34: 0.023968827 | E34: 0.018301072 | F34: 0.0089252616
A36: IRR: takeover premium vs. exit multiple change
A37: ='Returns Analysis'!B16 -> 0.047199619 | B37: -1 | C37: -0.5 | D37: 0 | E37: 0.5 | F37: 1
A38: 0.25 | B38: -0.062763587 | C38: 0.016709679 | D38: 0.073772342 | E38: 0.12078336 | F38: 0.16101827
A39: 0.3 | B39: -0.075579413 | C39: 0.0038574744 | D39: 0.059934187 | E39: 0.10616955 | F39: 0.14576074
A40: 0.35 | B40: -0.087410792 | C40: -0.0086622073 | D40: 0.047199619 | E40: 0.092712942 | F40: 0.13170558
A41: 0.4 | B41: -0.098388053 | C41: -0.020586711 | D41: 0.035421783 | E41: 0.080259749 | F41: 0.11869309
A42: 0.45 | B42: -0.10861785 | C42: -0.031699248 | D42: 0.024480541 | E42: 0.06868414 | F42: 0.10659264
A44: Scenario summary (one-variable data table on the scenario switch)
A45: Scenario | B45: # | C45: IRR | D45: MOIC | E45: Exit Net Debt/EBITDA | F45: Min EBITDA/Net Int. | G45: Min (EBITDA-Capex-SAC)/Int. | H45: Exit EV/EBITDA
A46: Active scenario (table header row) | C46: ='Returns Analysis'!B16 -> 0.047199619 | D46: ='Returns Analysis'!B15 -> 1.2593527 | E46: ='Returns Analysis'!B43 -> 2.794452 | F46: ='Returns Analysis'!B44 -> 3.3561332 | G46: ='Returns Analysis'!B45 -> 1.7129068 | H46: ='Returns Analysis'!B6 -> 4.7698212
...

Sheet Calibration
A1: Calibration: does the model's cash-flow method reproduce ADT's reported free cash flow? ($mm)
A2: Inputs from ADT's cash flow statements (FY2025 10-K; Q2 2026 10-Q). LTM = FY2025 + H1 2026 - H1 2025.
B3: FY2025 | C3: H1 2026 | D3: H1 2025 | E3: LTM Jun-26
A4: Revenue | B4: 5129 | C4: 2591 | D4: 2555 | E4: =B4+C4-D4 -> 5165
A5: Adjusted EBITDA | B5: 2680 | C5: 1345 | D5: 1335 | E5: =B5+C5-D5 -> 2690
A6: Dealer-generated accounts & bulk account purchases | B6: 596 | C6: 239 | D6: 331 | E6: =B6+C6-D6 -> 504
A7: Subscriber system asset expenditures | B7: 396 | C7: 170 | D7: 209 | E7: =B7+C7-D7 -> 357
A8: Purchases of property & equipment | B8: 176 | C8: 95 | D8: 83 | E8: =B8+C8-D8 -> 188
A9: Total capex (all-in) | B9: =SUM(B6:B8) -> 1168 | C9: =SUM(C6:C8) -> 504 | D9: =SUM(D6:D8) -> 623 | E9: =SUM(E6:E8) -> 1049
A10: Deferred subscriber acquisition costs (cash outflow) | B10: 381 | C10: 194 | D10: 189 | E10: =B10+C10-D10 -> 386
A11: Deferred subscriber acquisition revenue (cash inflow) | B11: 225 | C11: 98 | D11: 115 | E11: =B11+C11-D11 -> 208
A12: Net subscriber acquisition cost | B12: =B10-B11 -> 156 | C12: =C10-C11 -> 96 | D12: =D10-D11 -> 74 | E12: =E10-E11 -> 178
A13: Interest expense, net | B13: 459 | C13: 201 | D13: 237 | E13: =B13+C13-D13 -> 423
A14: Interest-rate swap settlements outside operating cash flow | B14: 65 | C14: 25 | D14: 33 | E14: =B14+C14-D14 -> 57
A15: Depreciation & intangible amortization | B15: 1367 | C15: 692 | D15: 678 | E15: =B15+C15-D15 -> 1381
A16: REPORTED Adjusted FCF (incl. swaps) | B16: 863 | C16: 820 | D16: 500 | E16: =B16+C16-D16 -> 1183
A18: Capex % of revenue | B18: =B9/B4 -> 0.2277247 | E18: =E9/E4 -> 0.20309777 | F18: Model base case uses 22.0%.
A19: Net SAC % of revenue | B19: =B12/B4 -> 0.030415286 | E19: =E12/E4 -> 0.03446273 | F19: Model base case uses 3.5%.
A21: Model cash-flow method applied to ADT's own existing capital structure
A22: Tax rate (from Assumptions) | B22: =Assumptions!$B$67 -> 0.26 | E22: =Assumptions!$B$67 -> 0.26
A23: Pre-tax income proxy (EBITDA - D&A - net interest) | B23: =B5-B15-B13 -> 854 | E23: =E5-E15-E13 -> 886
A24: Less: Taxes at model rate | B24: =MAX(B23,0)*B22 -> 222.04 | E24: =MAX(E23,0)*E22 -> 230.36
A25: Model FCF = EBITDA - capex - net SAC - net interest + swaps - taxes | B25: =B5-B9-B12-B13+B14-B24 -> 739.96 | E25: =E5-E9-E12-E13+E14-E24 -> 866.64
A26: Model FCF vs. reported Adj. FCF ($) | B26: =B25-B16 -> -123.04 | E26: =E25-E16 -> -316.36 | F26: Negative = model is more conservative than reported.
A27: Model FCF vs. reported Adj. FCF (%) | B27: =B25/B16-1 -> -0.14257242 | E27: =E25/E16-1 -> -0.26742181
A29: Reading this: the method lands ~14% below reported FY2025 Adjusted FCF and ~27% below LTM, so the model understates ADT's cash generation. Main drivers:
A30: (1) Taxes: the model charges full book tax; ADT's cash taxes are lower (deferred taxes were $142mm of $233mm FY2025 expense). At a 10% cash tax rate the base-case IRR would be ~7.1%.
A31: (2) Working-capital and other operating items are not modeled beyond the NWC % in Assumptions.
A32: The LTM gap is wider because H1 2026 reported FCF benefited from lower cash taxes and working-capital timing (per ADT's Q2 release).
A33: Capex is all-in (dealer accounts + subscriber systems + PP&E): roughly $1.0-1.2bn a year, or 20-23% of revenue.
